// function getLength(name) {
//     return name.getLength;
// }

// if no exception occurs then it proceeds to line 12
try { 
    // const ans = getLength();
    // console.log(ans);
    let a;
    console.log(a.length);
    console.log("hi there from inside try block");
} catch(e) {
    console.log("inside catch block");   
}
console.log("hi there");
